Workbook

Sheet Mode d'emploi
A1: Métré — Relecture des valeurs par défaut
A2: Version du code : Documents › code › projets › moteur-calculateurs, extraction du 4 octobre 2026.
A4: Pourquoi : chaque calculateur affiche « Valeurs vérifiées le … ». Cette mention doit correspondre à une relecture réelle par un professionnel du métier.
A5: Un onglet par corps de métier : on peut confier chaque onglet à l’artisan concerné.
A7: À remplir (cellules jaunes) :
A8: • Avis : OK, À corriger, Dépend du produit ou Je ne sais pas (liste déroulante).
A9: • Valeur proposée : seulement si l’avis est « À corriger ».
A10: • Commentaire ou source : fiche fabricant, DTU, habitude de chantier…
A11: • Relu par et date : en haut de chaque onglet.
A13: Catégories :
A14: 1. Ratio ou consommation : marges, rendements, consommations, recouvrements, entraxes. À relire en priorité (lignes rosées).
A15: 2. Format de produit : poids des sacs, longueurs et surfaces des produits vendus.
... A19: Exemple de ligne remplie :
A20: Calculateur | B20: Champ | C20: Catégorie | D20: Valeur par défaut | E20: Unité | F20: Bornes | G20: Aide affichée ou options | H20: Avis | I20: Valeur proposée | J20: Commentaire ou source
A21: Carrelage | B21: Marge pour la casse (marge) | C21: 1. Ratio ou consommation | D21: 5 | E21: % | F21: 0 à 50 | G21: Carreaux cassés à la coupe… | H21: À corriger | I21: 10 | J21: En grand format, je compte plutôt 10 %.

Sheet Gros œuvre et maçonnerie
A1: Gros œuvre et maçonnerie
A2: Relu par : | C2: Date :
A4: Calculateur | B4: Champ | C4: Catégorie | D4: Valeur par défaut | E4: Unité | F4: Bornes | G4: Aide affichée ou options | H4: Avis | I4: Valeur proposée | J4: Commentaire ou source
A5: parpaings, briques et blocs pour un mur | B5: Épaisseur du joint, format autre (jointAutre) | C5: 1. Ratio ou consommation | D5: 10 | E5: mm | F5: 0 à 30
A6: parpaings, briques et blocs pour un mur | B6: Marge pour la casse et les coupes (marge) | C6: 1. Ratio ou consommation | D6: 5 | E6: % | F6: 0 à 30
A7: parpaings, briques et blocs pour un mur | B7: Mortier ou colle (mortier) | C7: 1. Ratio ou consommation | D7: 20 | E7: kg par m² | F7: 0 à — | G7: Selon le fabricant : environ 20 à 25 kg par m² pour un parpaing monté au mortier, quelques kg en joint mince collé.
A8: parpaings, briques et blocs pour un mur | B8: Section de béton d’un chaînage (sectionChainage) | C8: 1. Ratio ou consommation | D8: 300 | E8: cm² | F8: 50 à — | G8: 15 × 20 cm = 300 cm² ; selon le bloc de chaînage utilisé.
A9: parpaings, briques et blocs pour un mur | B9: Enduit hydrofuge par m² (consommationHydrofuge) | C9: 1. Ratio ou consommation | D9: 20 | E9: kg | F9: 0 à — | G9: Selon l’épaisseur : environ 1,5 à 2 kg par m² et par mm.
A10: terrassement et de déblai avec foisonnement | B10: Coefficient de foisonnement personnalisé (coefficient) | C10: 1. Ratio ou consommation | F10: 1 à 2.5 | G10: Laissez vide pour le coefficient de la nature du sol.
A11: treillis soudé pour une dalle | B11: Recouvrement entre panneaux (recouvrement) | C11: 1. Ratio ou consommation | D11: 20 | E11: cm | F11: 0 à 100 | G11: Souvent deux mailles ; la valeur exacte dépend du treillis et de l’ouvrage : à vérifier.
A12: treillis soudé pour une dalle | B12: Cales d’enrobage par m² (calesM2) | C12: 1. Ratio ou consommation | D12: 4 | F12: 0 à — | G12: Valeur indicative, à vérifier : elles maintiennent le treillis dans l’épaisseur du béton.
A13: longueurs de linteaux | B13: Appui de chaque côté (appui) | C13: 1. Ratio ou consommation | D13: 20 | E13: cm | F13: 5 à — | G13: Longueur posée sur la maçonnerie de part et d’autre, selon le fabricant.
A14: longueurs de linteaux | B14: Pas des longueurs vendues (pas) | C14: 1. Ratio ou consommation | D14: 0.2 | E14: m | F14: 0.05 à — | G14: Les linteaux préfabriqués existent souvent de 20 cm en 20 cm.
A15: volume de béton | B15: Marge de sécurité (marge) | C15: 1. Ratio ou consommation | D15: 5 | E15: % | F15: 0 à 30
A16: volume de béton | B16: Béton obtenu avec un sac prêt à gâcher (rendementSac) | C16: 1. Ratio ou consommation | D16: 12 | E16: litres | F16: 1 à — | G16: Indiqué sur le sac (souvent 11 à 13 L pour 25 kg).
A17: un drainage périphérique | B17: Épaisseur du lit de gravier (epaisseurGravier) | C17: 1. Ratio ou consommation | D17: 30 | E17: cm | F17: 10 à —
A18: un escalier : formule de Blondel | B18: Valeur de Blondel visée (blondel) | C18: 1. Ratio ou consommation | D18: 63 | E18: cm | F18: 58 à 66 | G18: 2 × hauteur + giron, entre 60 et 64 cm pour un pas confortable.
A19: parpaings, briques et blocs pour un mur | B19: Hauteur du bloc, format autre (hauteurBloc) | C19: 2. Format de produit | D19: 20 | E19: cm | F19: 1 à —
A20: parpaings, briques et blocs pour un mur | B20: Longueur du bloc, format autre (longueurBloc) | C20: 2. Format de produit | D20: 50 | E20: cm | F20: 1 à —
A21: parpaings, briques et blocs pour un mur | B21: Poids d’un sac de mortier ou de colle (poidsSac) | C21: 2. Format de produit | D21: 25 | E21: kg | F21: 1 à —
A22: terrassement et de déblai avec foisonnement | B22: Profondeur moyenne (profondeur) | C22: 2. Format de produit | D22: 0.4 | E22: m | F22: 0.05 à 20
A23: terrassement et de déblai avec foisonnement | B23: Contenance d’une benne ou d’un camion (capacite) | C23: 2. Format de produit | D23: 10 | E23: m³ | F23: 0.5 à 40 | G23: Mini-benne : 3 à 6 m³ ; camion benne : environ 10 à 15 m³.
A24: treillis soudé pour une dalle | B24: Longueur d’un panneau (longueurPanneau) | C24: 2. Format de produit | D24: 6 | E24: m | F24: 1 à 12 | G24: Format courant : 6,00 × 2,40 m.
A25: treillis soudé pour une dalle | B25: Largeur d’un panneau (largeurPanneau) | C25: 2. Format de produit | D25: 2.4 | E25: m | F25: 0.5 à 4
A26: volume de béton | B26: Poids d’un sac de ciment (poidsSacCiment) | C26: 2. Format de produit | D26: 35 | E26: kg | F26: 1 à —
A27: un drainage périphérique | B27: Longueur d’un rouleau de drain (longueurRouleauDrain) | C27: 2. Format de produit | D27: 50 | E27: m | F27: 5 à —
A28: un drainage périphérique | B28: Surface d’un rouleau de membrane (surfaceMembrane) | C28: 2. Format de produit | D28: 40 | E28: m² | F28: 1 à —
A29: un drainage périphérique | B29: Surface d’un rouleau de géotextile (surfaceGeotextile) | C29: 2. Format de produit | D29: 50 | E29: m² | F29: 1 à —
A30: parpaings, briques et blocs pour un mur | B30: Type de bloc (bloc) | C30: 3. Choix proposé | D30: 0 | G30: Options : Parpaing 20 × 50 cm, joint de 1 cm | Brique de construction 20 × 50 cm, joint mince collé | Béton cellulaire 25 × 62,5 cm, joint mince collé | Carreau de plâtre 50 × 66 cm, collé | Autre format : dimensions ci-dessous
A31: parpaings, briques et blocs pour un mur | B31: Prévoir les chaînages (chainages) | C31: 3. Choix proposé | D31: Non cochée | G31: Chaînage horizontal en haut du mur et chaînage vertical à chaque angle, en armatures préfabriquées.
A32: terrassement et de déblai avec foisonnement | B32: Nature du sol (sol) | C32: 3. Choix proposé | D32: 1.25 | G32: Options : Sable, gravier (1,12) | Terre végétale ou terre ordinaire (1,25) | Argile (1,35) | Roche fragmentée (1,50) Coefficients de foisonnement d’usage (tables de travaux publics), variables selon l’humidité : à vérifier.
A33: volume de béton | B33: Ouvrage (ouvrage) | C33: 3. Choix proposé | D33: 0 | G33: Options : Dalle ou dallage | Semelle filante (fondation) | Poteaux ou plots
A34: volume de béton | B34: Fourniture du béton (fourniture) | C34: 3. Choix proposé | D34: 0 | G34: Options : Gâché sur place : ciment, sable, gravier | Béton prêt à l’emploi livré en toupie | Sacs de béton prêt à gâcher
A35: volume de béton | B35: Dosage en ciment (béton gâché) (dosage) | C35: 3. Choix proposé | D35: 350 | G35: Options : 250 kg/m³ : béton de propreté | 300 kg/m³ : fondations, dallage courant | 350 kg/m³ : béton armé, dalle, poteaux

Sheet Synthèse
A1: Avancement de la relecture
A3: Corps de métier | B3: Valeurs à relire | C3: Dont prioritaires | D3: OK | E3: À corriger | F3: Dépend du produit | G3: Je ne sais pas | H3: Sans avis | I3: Relu par
A4: Gros œuvre et maçonnerie | B4: =COUNTA('Gros œuvre et maçonnerie'!B5:B500) -> 31 | C4: =COUNTIF('Gros œuvre et maçonnerie'!C5:C500,"1. *") -> 14 | D4: =COUNTIF('Gros œuvre et maçonnerie'!H5:H500,"OK") -> 0 | E4: =COUNTIF('Gros œuvre et maçonnerie'!H5:H500,"À corriger") -> 0 | F4: =COUNTIF('Gros œuvre et maçonnerie'!H5:H500,"Dépend du produit") -> 0 | G4: =COUNTIF('Gros œuvre et maçonnerie'!H5:H500,"Je ne sais pas") -> 0 | H4: =B4-D4-E4-F4-G4 -> 31 | I4: ='Gros œuvre et maçonnerie'!B2&""
A5: Aménagements extérieurs | B5: =COUNTA('Aménagements extérieurs'!B5:B500) -> 25 | C5: =COUNTIF('Aménagements extérieurs'!C5:C500,"1. *") -> 11 | D5: =COUNTIF('Aménagements extérieurs'!H5:H500,"OK") -> 0 | E5: =COUNTIF('Aménagements extérieurs'!H5:H500,"À corriger") -> 0 | F5: =COUNTIF('Aménagements extérieurs'!H5:H500,"Dépend du produit") -> 0 | G5: =COUNTIF('Aménagements extérieurs'!H5:H500,"Je ne sais pas") -> 0 | H5: =B5-D5-E5-F5-G5 -> 25 | I5: ='Aménagements extérieurs'!B2&""
A6: Plâtrerie et isolation | B6: =COUNTA('Plâtrerie et isolation'!B5:B500) -> 43 | C6: =COUNTIF('Plâtrerie et isolation'!C5:C500,"1. *") -> 19 | D6: =COUNTIF('Plâtrerie et isolation'!H5:H500,"OK") -> 0 | E6: =COUNTIF('Plâtrerie et isolation'!H5:H500,"À corriger") -> 0 | F6: =COUNTIF('Plâtrerie et isolation'!H5:H500,"Dépend du produit") -> 0 | G6: =COUNTIF('Plâtrerie et isolation'!H5:H500,"Je ne sais pas") -> 0 | H6: =B6-D6-E6-F6-G6 -> 43 | I6: ='Plâtrerie et isolation'!B2&""
A7: Menuiserie | B7: =COUNTA(Menuiserie!B5:B500) -> 18 | C7: =COUNTIF(Menuiserie!C5:C500,"1. *") -> 7 | D7: =COUNTIF(Menuiserie!H5:H500,"OK") -> 0 | E7: =COUNTIF(Menuiserie!H5:H500,"À corriger") -> 0 | F7: =COUNTIF(Menuiserie!H5:H500,"Dépend du produit") -> 0 | G7: =COUNTIF(Menuiserie!H5:H500,"Je ne sais pas") -> 0 | H7: =B7-D7-E7-F7-G7 -> 18 | I7: =Menuiserie!B2&""
A8: Plomberie, chauffage et ventilation | B8: =COUNTA('Plomberie, chauffage et ventila'!B5:B500) -> 21 | C8: =COUNTIF('Plomberie, chauffage et ventila'!C5:C500,"1. *") -> 3 | D8: =COUNTIF('Plomberie, chauffage et ventila'!H5:H500,"OK") -> 0 | E8: =COUNTIF('Plomberie, chauffage et ventila'!H5:H500,"À corriger") -> 0 | F8: =COUNTIF('Plomberie, chauffage et ventila'!H5:H500,"Dépend du produit") -> 0 | G8: =COUNTIF('Plomberie, chauffage et ventila'!H5:H500,"Je ne sais pas") -> 0 | H8: =B8-D8-E8-F8-G8 -> 21 | I8: ='Plomberie, chauffage et ventila'!B2&""
A9: Électricité | B9: =COUNTA(Électricité!B5:B500) -> 8 | C9: =COUNTIF(Électricité!C5:C500,"1. *") -> 1 | D9: =COUNTIF(Électricité!H5:H500,"OK") -> 0 | E9: =COUNTIF(Électricité!H5:H500,"À corriger") -> 0 | F9: =COUNTIF(Électricité!H5:H500,"Dépend du produit") -> 0 | G9: =COUNTIF(Électricité!H5:H500,"Je ne sais pas") -> 0 | H9: =B9-D9-E9-F9-G9 -> 8 | I9: =Électricité!B2&""
A10: Sols | B10: =COUNTA(Sols!B5:B500) -> 70 | C10: =COUNTIF(Sols!C5:C500,"1. *") -> 23 | D10: =COUNTIF(Sols!H5:H500,"OK") -> 0 | E10: =COUNTIF(Sols!H5:H500,"À corriger") -> 0 | F10: =COUNTIF(Sols!H5:H500,"Dépend du produit") -> 0 | G10: =COUNTIF(Sols!H5:H500,"Je ne sais pas") -> 0 | H10: =B10-D10-E10-F10-G10 -> 70 | I10: =Sols!B2&""
A11: Murs intérieurs | B11: =COUNTA('Murs intérieurs'!B5:B500) -> 32 | C11: =COUNTIF('Murs intérieurs'!C5:C500,"1. *") -> 13 | D11: =COUNTIF('Murs intérieurs'!H5:H500,"OK") -> 0 | E11: =COUNTIF('Murs intérieurs'!H5:H500,"À corriger") -> 0 | F11: =COUNTIF('Murs intérieurs'!H5:H500,"Dépend du produit") -> 0 | G11: =COUNTIF('Murs intérieurs'!H5:H500,"Je ne sais pas") -> 0 | H11: =B11-D11-E11-F11-G11 -> 32 | I11: ='Murs intérieurs'!B2&""
A12: Façades | B12: =COUNTA(Façades!B5:B500) -> 23 | C12: =COUNTIF(Façades!C5:C500,"1. *") -> 12 | D12: =COUNTIF(Façades!H5:H500,"OK") -> 0 | E12: =COUNTIF(Façades!H5:H500,"À corriger") -> 0 | F12: =COUNTIF(Façades!H5:H500,"Dépend du produit") -> 0 | G12: =COUNTIF(Façades!H5:H500,"Je ne sais pas") -> 0 | H12: =B12-D12-E12-F12-G12 -> 23 | I12: =Façades!B2&""
A13: Charpente | B13: =COUNTA(Charpente!B5:B500) -> 3 | C13: =COUNTIF(Charpente!C5:C500,"1. *") -> 0 | D13: =COUNTIF(Charpente!H5:H500,"OK") -> 0 | E13: =COUNTIF(Charpente!H5:H500,"À corriger") -> 0 | F13: =COUNTIF(Charpente!H5:H500,"Dépend du produit") -> 0 | G13: =COUNTIF(Charpente!H5:H500,"Je ne sais pas") -> 0 | H13: =B13-D13-E13-F13-G13 -> 3 | I13: =Charpente!B2&""
A14: Couverture | B14: =COUNTA(Couverture!B5:B500) -> 32 | C14: =COUNTIF(Couverture!C5:C500,"1. *") -> 12 | D14: =COUNTIF(Couverture!H5:H500,"OK") -> 0 | E14: =COUNTIF(Couverture!H5:H500,"À corriger") -> 0 | F14: =COUNTIF(Couverture!H5:H500,"Dépend du produit") -> 0 | G14: =COUNTIF(Couverture!H5:H500,"Je ne sais pas") -> 0 | H14: =B14-D14-E14-F14-G14 -> 32 | I14: =Couverture!B2&""
A15: Total | B15: =SUM(B4:B14) -> 306 | C15: =SUM(C4:C14) -> 115 | D15: =SUM(D4:D14) -> 0 | E15: =SUM(E4:E14) -> 0 | F15: =SUM(F4:F14) -> 0 | G15: =SUM(G4:G14) -> 0 | H15: =SUM(H4:H14) -> 306

Sheet Aménagements extérieurs
A1: Aménagements extérieurs
A2: Relu par : | C2: Date :
A4: Calculateur | B4: Champ | C4: Catégorie | D4: Valeur par défaut | E4: Unité | F4: Bornes | G4: Aide affichée ou options | H4: Avis | I4: Valeur proposée | J4: Commentaire ou source
A5: gravier, sable et remblai en tonnes | B5: Marge de tassement (marge) | C5: 1. Ratio ou consommation | D5: 10 | E5: % | F5: 0 à 40
A6: pavés, sable et grave pour une allée | B6: Pavés au m² (pavesM2) | C6: 1. Ratio ou consommation | D6: 50 | F6: 1 à — | G6: Indiqué par le fabricant ; environ 50 pour un pavé de 20 × 10 cm.
A7: pavés, sable et grave pour une allée | B7: Épaisseur du lit de sable (litPose) | C7: 1. Ratio ou consommation | D7: 4 | E7: cm | F7: 1 à 10
A8: pavés, sable et grave pour une allée | B8: Marge pour les coupes (marge) | C8: 1. Ratio ou consommation | D8: 5 | E8: % | F8: 0 à 30
A9: une clôture : panneaux, grillage et poteaux | B9: Côté du trou de scellement (coteTrou) | C9: 1. Ratio ou consommation | D9: 30 | E9: cm | F9: 10 à —
A10: une clôture : panneaux, grillage et poteaux | B10: Profondeur du trou de scellement (profondeurTrou) | C10: 1. Ratio ou consommation | D10: 50 | E10: cm | F10: 20 à —
A11: une clôture : panneaux, grillage et poteaux | B11: Béton obtenu avec un sac prêt à gâcher (rendementSac) | C11: 1. Ratio ou consommation | D11: 12 | E11: litres | F11: 1 à —
A12: une terrasse en lames bois ou composite | B12: Espacement entre lames (espacement) | C12: 1. Ratio ou consommation | D12: 5 | E12: mm | F12: 0 à 15
A13: une terrasse en lames bois ou composite | B13: Écartement des plots sous une lambourde (entraxePlots) | C13: 1. Ratio ou consommation | D13: 60 | E13: cm | F13: 20 à —
A14: une terrasse en lames bois ou composite | B14: Vis ou clips par boîte (fixationsParBoite) | C14: 1. Ratio ou consommation | D14: 200 | F14: 1 à —
A15: une terrasse en lames bois ou composite | B15: Marge pour les coupes (marge) | C15: 1. Ratio ou consommation | D15: 10 | E15: % | F15: 0 à 30
A16: gravier, sable et remblai en tonnes | B16: Poids d’un sac (poidsSac) | C16: 2. Format de produit | D16: 25 | E16: kg | F16: 1 à —
A17: gravier, sable et remblai en tonnes | B17: Poids d’un big bag (poidsBigBag) | C17: 2. Format de produit | D17: 1000 | E17: kg | F17: 100 à —
A18: pavés, sable et grave pour une allée | B18: Surface d’un rouleau de géotextile (surfaceGeotextile) | C18: 2. Format de produit | D18: 50 | E18: m² | F18: 1 à —
A19: une clôture : panneaux, grillage et poteaux | B19: Largeur d’un panneau, ou écart entre poteaux pour le grillage (largeurPanneau) | C19: 2. Format de produit | D19: 2.5 | E19: m | F19: 0.5 à 5
A20: une clôture : panneaux, grillage et poteaux | B20: Longueur d’un rouleau de grillage (longueurRouleau) | C20: 2. Format de produit | D20: 25 | E20: m | F20: 5 à —
A21: une terrasse en lames bois ou composite | B21: Largeur d’une lame (largeurLame) | C21: 2. Format de produit | D21: 14.5 | E21: cm | F21: 5 à 40
A22: une terrasse en lames bois ou composite | B22: Longueur d’une lame (longueurLame) | C22: 2. Format de produit | D22: 2.4 | E22: m | F22: 0.5 à 6
A23: une terrasse en lames bois ou composite | B23: Longueur d’une lambourde (longueurLambourde) | C23: 2. Format de produit | D23: 4 | E23: m | F23: 1 à —
A24: gravier, sable et remblai en tonnes | B24: Matériau (materiau) | C24: 3. Choix proposé | D24: 1.5 | G24: Options : Gravier ou gravillon décoratif (1,5 t/m³) | Sable, galets (1,6 t/m³) | Terre végétale (1,3 t/m³) | Tout-venant ou grave compactée (2 t/m³)
A25: pavés, sable et grave pour une allée | B25: Usage (usage) | C25: 3. Choix proposé | D25: 15 | G25: Options : Piétons : environ 15 cm de fondation | Véhicules légers : environ 25 cm de fondation
A26: une clôture : panneaux, grillage et poteaux | B26: Type de clôture (type) | C26: 3. Choix proposé | D26: 0 | G26: Options : Panneaux rigides | Grillage souple en rouleau
A27: une clôture : panneaux, grillage et poteaux | B27: Fixation des poteaux (scellement) | C27: 3. Choix proposé | D27: 0 | G27: Options : Scellés au béton | Sur platines, fixées sur un muret ou une dalle
A28: une terrasse en lames bois ou composite | B28: Entraxe des lambourdes (entraxe) | C28: 3. Choix proposé | D28: 50 | G28: Options : 50 cm, lames bois courantes | 40 cm, lames composites | 60 cm, lames bois épaisses
A29: une terrasse en lames bois ou composite | B29: Fixation des lames (fixation) | C29: 3. Choix proposé | D29: 2 | G29: Options : Vis : 2 par lame et par lambourde | Clips invisibles : 1 par croisement

Sheet Plâtrerie et isolation
A1: Plâtrerie et isolation
A2: Relu par : | C2: Date :
A4: Calculateur | B4: Champ | C4: Catégorie | D4: Valeur par défaut | E4: Unité | F4: Bornes | G4: Aide affichée ou options | H4: Avis | I4: Valeur proposée | J4: Commentaire ou source
A5: la quantité de laine de roche | B5: Résistance thermique visée (R) (resistance) | C5: 1. Ratio ou consommation | D5: 7 | E5: m².K/W | F5: 0.5 à 15 | G5: Fixée par votre projet ou par les conditions des aides à la rénovation.
A6: la quantité de laine de roche | B6: Conductivité thermique de l’isolant (λ) (lambda) | C6: 1. Ratio ou consommation | D6: 0.035 | E6: W/m.K | F6: 0.015 à 0.1 | G6: Inscrite sur l’emballage : plus elle est basse, plus l’isolant est performant à épaisseur égale.
A7: la quantité de laine de roche | B7: Marge pour les découpes (marge) | C7: 1. Ratio ou consommation | D7: 5 | E7: % | F7: 0 à 50
A8: la quantité de laine de roche | B8: Surface d’un rouleau de pare-vapeur (surfacePareVapeur) | C8: 1. Ratio ou consommation | D8: 40 | E8: m² | F8: 1 à —
A9: la quantité de laine de roche | B9: Adhésif par m² de pare-vapeur (adhesifM2) | C9: 1. Ratio ou consommation | D9: 1 | E9: m | F9: 0 à — | G9: Raccords entre lés et en périphérie : environ 1 m par m².
A10: la quantité de laine de verre | B10: Résistance thermique visée (R) (resistance) | C10: 1. Ratio ou consommation | D10: 7 | E10: m².K/W | F10: 0.5 à 15 | G10: Fixée par votre projet ou par les conditions des aides à la rénovation.
A11: la quantité de laine de verre | B11: Conductivité thermique de l’isolant (λ) (lambda) | C11: 1. Ratio ou consommation | D11: 0.032 | E11: W/m.K | F11: 0.015 à 0.1 | G11: Inscrite sur l’emballage : plus elle est basse, plus l’isolant est performant à épaisseur égale.
A12: la quantité de laine de verre | B12: Marge pour les découpes (marge) | C12: 1. Ratio ou consommation | D12: 5 | E12: % | F12: 0 à 50
A13: la quantité de laine de verre | B13: Surface d’un rouleau de pare-vapeur (surfacePareVapeur) | C13: 1. Ratio ou consommation | D13: 40 | E13: m² | F13: 1 à —
A14: la quantité de laine de verre | B14: Adhésif par m² de pare-vapeur (adhesifM2) | C14: 1. Ratio ou consommation | D14: 1 | E14: m | F14: 0 à — | G14: Raccords entre lés et en périphérie : environ 1 m par m².
A15: plaques de plâtre, rails et montants | B15: Marge pour les coupes et la casse (marge) | C15: 1. Ratio ou consommation | D15: 5 | E15: % | F15: 0 à 50
A16: plaques de plâtre, rails et montants | B16: Vis par plaque (visParPlaque) | C16: 1. Ratio ou consommation | D16: 25 | F16: 0 à — | G16: Indicatif : une vis tous les 30 cm au plus sur chaque montant. Vérifiez la fiche du fabricant.
A17: plaques de plâtre, rails et montants | B17: Enduit à joint par m² de parement (enduitM2) | C17: 1. Ratio ou consommation | D17: 0.35 | E17: kg | F17: 0 à — | G17: Indiqué sur le sac ou le seau ; environ 0,3 à 0,4 kg par m².
A18: isolation soufflée des combles | B18: Résistance thermique visée (R) (resistance) | C18: 1. Ratio ou consommation | D18: 7 | E18: m².K/W | F18: 1 à 12
A19: isolation soufflée des combles | B19: Conductivité thermique (λ), si différente (lambda) | C19: 1. Ratio ou consommation | D19: 0 | E19: W/m.K | F19: 0 à 0.1 | G19: 0 : valeur courante du produit choisi.
A20: isolation soufflée des combles | B20: Masse volumique en place, si différente (masseVolumique) | C20: 1. Ratio ou consommation | D20: 0 | E20: kg/m³ | F20: 0 à 80 | G20: 0 : valeur courante du produit choisi.
A21: un plafond suspendu en plaques de plâtre | B21: Espacement des suspentes sur une fourrure (espacementSuspentes) | C21: 1. Ratio ou consommation | D21: 1.2 | E21: m | F21: 0.3 à —
A22: un plafond suspendu en plaques de plâtre | B22: Vis par plaque (visParPlaque) | C22: 1. Ratio ou consommation | D22: 40 | F22: 0 à — | G22: Indicatif : une vis tous les 20 cm environ sur chaque fourrure.
A23: un plafond suspendu en plaques de plâtre | B23: Marge pour les coupes (marge) | C23: 1. Ratio ou consommation | D23: 5 | E23: % | F23: 0 à 30
A24: la quantité de laine de roche | B24: Épaisseur d’un rouleau ou d’un panneau (epaisseurProduit) | C24: 2. Format de produit | D24: 20 | E24: cm | F24: 1 à —
A25: la quantité de laine de roche | B25: Surface couverte par un colis (surfaceColis) | C25: 2. Format de produit | D25: 3 | E25: m² | F25: 0.1 à — | G25: Inscrite sur l’emballage du rouleau ou du paquet de panneaux.
A26: la quantité de laine de roche | B26: Longueur d’un rouleau d’adhésif (longueurAdhesif) | C26: 2. Format de produit | D26: 25 | E26: m | F26: 1 à —
A27: la quantité de laine de verre | B27: Épaisseur d’un rouleau ou d’un panneau (epaisseurProduit) | C27: 2. Format de produit | D27: 20 | E27: cm | F27: 1 à —
A28: la quantité de laine de verre | B28: Surface couverte par un colis (surfaceColis) | C28: 2. Format de produit | D28: 4 | E28: m² | F28: 0.1 à — | G28: Inscrite sur l’emballage du rouleau ou du paquet de panneaux.
A29: la quantité de laine de verre | B29: Longueur d’un rouleau d’adhésif (longueurAdhesif) | C29: 2. Format de produit | D29: 25 | E29: m | F29: 1 à —
A30: plaques de plâtre, rails et montants | B30: Longueur d’un rail (longueurRail) | C30: 2. Format de produit | D30: 3 | E30: m | F30: 0.5 à —
A31: plaques de plâtre, rails et montants | B31: Poids d’un sac ou d’un seau d’enduit (poidsEnduit) | C31: 2. Format de produit | D31: 25 | E31: kg | F31: 1 à —
A32: plaques de plâtre, rails et montants | B32: Longueur d’un rouleau de bande à joint (longueurBande) | C32: 2. Format de produit | D32: 75 | E32: m | F32: 5 à —
A33: isolation soufflée des combles | B33: Poids d’un sac (poidsSac) | C33: 2. Format de produit | D33: 15 | E33: kg | F33: 1 à —
A34: un plafond suspendu en plaques de plâtre | B34: Longueur d’une fourrure ou d’une cornière (longueurFourrure) | C34: 2. Format de produit | D34: 3 | E34: m | F34: 1 à —
A35: la quantité de laine de roche | B35: Paroi à isoler (paroi) | C35: 3. Choix proposé | D35: 0 | G35: Options : Autre : résistance saisie ci-dessus | Combles perdus : R = 7 | Rampants ou plafond de combles aménagés : R = 6 | Murs : R = 3,7 | Plancher bas : R = 3 Résistances minimales demandées pour les aides à la rénovation (MaPrimeRénov’, CEE), à vérifier chaque année sur france-renov.gouv.fr.
A36: la quantité de laine de roche | B36: Prévoir un pare-vapeur et son adhésif d’étanchéité (pareVapeur) | C36: 3. Choix proposé | D36: Cochée | G36: Côté chauffé ; certains isolants ou systèmes n’en demandent pas : voir la notice.
A37: la quantité de laine de verre | B37: Paroi à isoler (paroi) | C37: 3. Choix proposé | D37: 0 | G37: Options : Autre : résistance saisie ci-dessus | Combles perdus : R = 7 | Rampants ou plafond de combles aménagés : R = 6 | Murs : R = 3,7 | Plancher bas : R = 3 Résistances minimales demandées pour les aides à la rénovation (MaPrimeRénov’, CEE), à vérifier chaque année sur france-renov.gouv.fr.
A38: la quantité de laine de verre | B38: Prévoir un pare-vapeur et son adhésif d’étanchéité (pareVapeur) | C38: 3. Choix proposé | D38: Cochée | G38: Côté chauffé ; certains isolants ou systèmes n’en demandent pas : voir la notice.
A39: plaques de plâtre, rails et montants | B39: Type d’ouvrage (ouvrage) | C39: 3. Choix proposé | D39: 2 | G39: Options : Cloison : plaques sur les deux faces | Doublage d’un mur : plaques sur une face
A40: plaques de plâtre, rails et montants | B40: Épaisseur de parement (peau) | C40: 3. Choix proposé | D40: 1 | G40: Options : Une plaque par face (simple peau) | Deux plaques par face (double peau, meilleure isolation phonique)
A41: plaques de plâtre, rails et montants | B41: Type de plaque (typePlaque) | C41: 3. Choix proposé | D41: 0 | G41: Options : Standard | Hydrofuge (pièces humides) | Phonique | Résistante au feu | Haute dureté Même calcul pour tous les types ; le type est repris dans le récapitulatif.
...

Sheet Menuiserie
A1: Menuiserie
A2: Relu par : | C2: Date :
A4: Calculateur | B4: Champ | C4: Catégorie | D4: Valeur par défaut | E4: Unité | F4: Bornes | G4: Aide affichée ou options | H4: Avis | I4: Valeur proposée | J4: Commentaire ou source
A5: lambris et de bardage | B5: Fixations par m² (fixationsM2) | C5: 1. Ratio ou consommation | D5: 20 | F5: 0 à — | G5: Pointes, agrafes, clips ou vis, selon la lame et la notice.
A6: lambris et de bardage | B6: Surface d’un rouleau de pare-pluie (surfacePareP) | C6: 1. Ratio ou consommation | D6: 75 | E6: m² | F6: 1 à —
A7: lambris et de bardage | B7: Marge pour les coupes en pose droite (marge) | C7: 1. Ratio ou consommation | D7: 10 | E7: % | F7: 0 à 30
A8: lambris et de bardage | B8: Taux de chute personnalisé (tauxChute) | C8: 1. Ratio ou consommation | E8: % | F8: 0 à 50 | G8: Laissez vide pour la marge ou le forfait de la pose.
A9: un plancher bois : solives et panneaux | B9: Appui à chaque extrémité (appui) | C9: 1. Ratio ou consommation | D9: 10 | E9: cm | F9: 0 à —
A10: un plancher bois : solives et panneaux | B10: Vis par m² de panneaux (visM2) | C10: 1. Ratio ou consommation | D10: 20 | F10: 0 à —
A11: un plancher bois : solives et panneaux | B11: Marge pour les coupes (marge) | C11: 1. Ratio ou consommation | D11: 5 | E11: % | F11: 0 à 30
A12: lambris et de bardage | B12: Largeur utile d’une lame (largeurUtile) | C12: 2. Format de produit | D12: 12 | E12: cm | F12: 3 à 40
A13: lambris et de bardage | B13: Longueur d’une lame (longueurLame) | C13: 2. Format de produit | D13: 2.5 | E13: m | F13: 0.5 à 6
A14: lambris et de bardage | B14: Longueur d’un tasseau (longueurTasseau) | C14: 2. Format de produit | D14: 2.4 | E14: m | F14: 0.5 à —
A15: un plancher bois : solives et panneaux | B15: Longueur maximale des solives vendues (longueurVendue) | C15: 2. Format de produit | D15: 5 | E15: m | F15: 1 à —
A16: un plancher bois : solives et panneaux | B16: Surface d’un panneau (surfacePanneau) | C16: 2. Format de produit | D16: 1.6875 | E16: m² | F16: 0.2 à — | G16: Panneau rainuré de 2,50 × 0,675 m : 1,6875 m².
A17: lambris et de bardage | B17: Usage (usage) | C17: 3. Choix proposé | D17: 0 | G17: Options : Lambris intérieur | Bardage de façade
A18: lambris et de bardage | B18: Sens de pose des lames (sens) | C18: 3. Choix proposé | D18: 0 | G18: Options : Lames horizontales, tasseaux verticaux | Lames verticales, tasseaux horizontaux
A19: lambris et de bardage | B19: Type de pose (poseLames) | C19: 3. Choix proposé | D19: 0 | G19: Options : Droite | En diagonale | En chevrons Pose droite : la marge des réglages avancés. Diagonale et chevrons : forfait, modifiable.
A20: lambris et de bardage | B20: Entraxe des tasseaux (entraxe) | C20: 3. Choix proposé | D20: 50 | G20: Options : 40 cm | 50 cm | 60 cm
A21: lambris et de bardage | B21: Prévoir un pare-pluie (bardage de façade) (pareP) | C21: 3. Choix proposé | D21: Non cochée
A22: un plancher bois : solives et panneaux | B22: Entraxe des solives (entraxe) | C22: 3. Choix proposé | D22: 50 | G22: Options : 40 cm | 50 cm | 60 cm

Sheet Plomberie, chauffage et ventila
A1: Plomberie, chauffage et ventilation
A2: Relu par : | C2: Date :
A4: Calculateur | B4: Champ | C4: Catégorie | D4: Valeur par défaut | E4: Unité | F4: Bornes | G4: Aide affichée ou options | H4: Avis | I4: Valeur proposée | J4: Commentaire ou source
A5: la capacité d’un ballon d’eau chaude | B5: Eau à 40 °C fournie par litre de ballon (V40) (coefficientV40) | C5: 1. Ratio ou consommation | D5: 1.8 | F5: 1 à 2.5 | G5: Environ 1,8 pour un ballon chauffé vers 60 °C ; la valeur exacte est sur la fiche du ballon.
A6: la capacité d’un ballon d’eau chaude | B6: Marge pour les pointes de consommation (marge) | C6: 1. Ratio ou consommation | D6: 50 | E6: % | F6: 0 à 100
A7: débit de VMC par pièce | B7: WC séparés (pièces WC) (wcSepares) | C7: 1. Ratio ou consommation | D7: 1 | F7: 0 à 10
A8: la puissance de chauffage nécessaire | B8: Température intérieure souhaitée (temperatureInterieure) | C8: 2. Format de produit | D8: 19 | E8: °C | F8: 10 à 26
A9: la puissance de chauffage nécessaire | B9: Température extérieure de base (temperatureExterieure) | C9: 2. Format de produit | D9: -7 | E9: °C | F9: -30 à 10 | G9: Température la plus froide retenue pour votre département : de -2 °C en bord de Méditerranée à -15 °C en montagne.
A10: la puissance de chauffage nécessaire | B10: Puissance d’un radiateur (puissanceRadiateur) | C10: 2. Format de produit | D10: 1000 | E10: W | F10: 100 à —
A11: débit de VMC par pièce | B11: Salles de bains ou de douches (sallesDeBains) | C11: 2. Format de produit | D11: 1 | F11: 0 à 10
A12: un réseau de plomberie par point d’eau | B12: Lavabos et vasques (lavabos) | C12: 2. Format de produit | D12: 1 | F12: 0 à 50
A13: un réseau de plomberie par point d’eau | B13: Éviers (eviers) | C13: 2. Format de produit | D13: 1 | F13: 0 à 20
A14: un réseau de plomberie par point d’eau | B14: Douches (douches) | C14: 2. Format de produit | D14: 1 | F14: 0 à 20
A15: un réseau de plomberie par point d’eau | B15: Baignoires (baignoires) | C15: 2. Format de produit | D15: 0 | F15: 0 à 20
A16: un réseau de plomberie par point d’eau | B16: WC (wc) | C16: 2. Format de produit | D16: 1 | F16: 0 à 20
A17: un réseau de plomberie par point d’eau | B17: Lave-linge (laveLinge) | C17: 2. Format de produit | D17: 1 | F17: 0 à 10
A18: un réseau de plomberie par point d’eau | B18: Lave-vaisselle (laveVaisselle) | C18: 2. Format de produit | D18: 1 | F18: 0 à 10
A19: un réseau de plomberie par point d’eau | B19: Distance moyenne nourrice – point d’eau (distanceAlimentation) | C19: 2. Format de produit | D19: 6 | E19: m | F19: 0.5 à 50
A20: un réseau de plomberie par point d’eau | B20: Distance moyenne point d’eau – chute (distanceEvacuation) | C20: 2. Format de produit | D20: 4 | E20: m | F20: 0.5 à 50
A21: un réseau de plomberie par point d’eau | B21: Longueur d’une couronne de tube (longueurCouronne) | C21: 2. Format de produit | D21: 50 | E21: m | F21: 5 à —
A22: un réseau de plomberie par point d’eau | B22: Longueur d’une barre de PVC (longueurBarre) | C22: 2. Format de produit | D22: 4 | E22: m | F22: 1 à —
A23: la puissance de chauffage nécessaire | B23: Niveau d’isolation (isolation) | C23: 3. Choix proposé | D23: 1 | G23: Options : Bonne : construction récente ou rénovation complète | Correcte : isolation des années 2000 | Moyenne : isolation partielle ou ancienne | Faible : logement peu ou pas isolé Coefficient indicatif de déperdition en W par m³ et par °C.
A24: débit de VMC par pièce | B24: Pièces principales (séjour et chambres) (pieces) | C24: 3. Choix proposé | D24: 4 | G24: Options : 1 | 2 | 3 | 4 | 5 | 6 | 7 et plus Un séjour ouvert sur une chambre sans cloison compte pour deux pièces principales.
A25: débit de VMC par pièce | B25: Un WC se trouve aussi dans une salle de bains (wcDansSalleDEau) | C25: 3. Choix proposé | D25: Non cochée | G25: Il compte pour savoir si les WC sont « multiples ».

Sheet Électricité
A1: Électricité
A2: Relu par : | C2: Date :
A4: Calculateur | B4: Champ | C4: Catégorie | D4: Valeur par défaut | E4: Unité | F4: Bornes | G4: Aide affichée ou options | H4: Avis | I4: Valeur proposée | J4: Commentaire ou source
A5: gaine, de fil et de boîtes électriques | B5: Longueur moyenne de gaine par point (longueurParPoint) | C5: 1. Ratio ou consommation | D5: 6 | E5: m | F5: 1 à 40 | G5: Du tableau ou du point précédent du même circuit : souvent 4 à 8 m dans une maison.
A6: gaine, de fil et de boîtes électriques | B6: Prises de courant (prises) | C6: 2. Format de produit | D6: 10 | F6: 0 à 200
A7: gaine, de fil et de boîtes électriques | B7: Points lumineux (pointsLumineux) | C7: 2. Format de produit | D7: 5 | F7: 0 à 100
A8: gaine, de fil et de boîtes électriques | B8: Interrupteurs et va-et-vient (interrupteurs) | C8: 2. Format de produit | D8: 5 | F8: 0 à 100
A9: gaine, de fil et de boîtes électriques | B9: Circuits spécialisés (circuitsSpecialises) | C9: 2. Format de produit | D9: 3 | F9: 0 à 30 | G9: Plaque de cuisson, four, lave-linge, lave-vaisselle, chauffe-eau…
A10: gaine, de fil et de boîtes électriques | B10: Conducteurs par gaine (conducteurs) | C10: 2. Format de produit | D10: 3 | F10: 2 à 5 | G10: Phase, neutre et terre.
A11: gaine, de fil et de boîtes électriques | B11: Longueur d’une couronne de gaine (longueurCouronneGaine) | C11: 2. Format de produit | D11: 50 | E11: m | F11: 5 à —
A12: gaine, de fil et de boîtes électriques | B12: Longueur d’une couronne de fil (longueurCouronneFil) | C12: 2. Format de produit | D12: 100 | E12: m | F12: 5 à —

Sheet Sols
A1: Sols
A2: Relu par : | C2: Date :
A4: Calculateur | B4: Champ | C4: Catégorie | D4: Valeur par défaut | E4: Unité | F4: Bornes | G4: Aide affichée ou options | H4: Avis | I4: Valeur proposée | J4: Commentaire ou source
A5: carrelage avec découpes | B5: Largeur des joints (joint) | C5: 1. Ratio ou consommation | D5: 3 | E5: mm | F5: 0 à 20
A6: carrelage avec découpes | B6: Carreaux par carton (carreauxParCarton) | C6: 1. Ratio ou consommation | D6: 6 | F6: 1 à — | G6: Indiqué sur l’étiquette du carton.
A7: carrelage avec découpes | B7: Marge pour la casse (marge) | C7: 1. Ratio ou consommation | D7: 5 | E7: % | F7: 0 à 50 | G7: Carreaux cassés à la coupe ou défectueux. Comptez davantage si vous débutez.
A8: carrelage avec découpes | B8: Consommation de colle (consommationColle) | C8: 1. Ratio ou consommation | D8: 5 | E8: kg par m² | F8: 0 à — | G8: Indiquée sur le sac ; elle augmente avec la taille des carreaux.
A9: carrelage avec découpes | B9: Croisillons par carreau (croisillonsParCarreau) | C9: 1. Ratio ou consommation | D9: 2 | F9: 0 à — | G9: Environ 1 en croix, jusqu’à 4 en T sur les côtés.
A10: carrelage avec découpes | B10: Cales autonivelantes par carreau (calesParCarreau) | C10: 1. Ratio ou consommation | D10: 3 | F10: 0 à —
A11: carrelage avec découpes | B11: Pièces par sachet d’accessoires (accessoiresParSachet) | C11: 1. Ratio ou consommation | D11: 100 | F11: 1 à —
A12: chape et de ragréage | B12: Consommation par millimètre (consommation) | C12: 1. Ratio ou consommation | D12: 1.6 | E12: kg par m² et par mm | F12: 0.5 à 3 | G12: Inscrite sur le sac : environ 1,5 à 1,7 pour un ragréage, environ 2 pour un mortier de chape.
A13: chape et de ragréage | B13: Marge (marge) | C13: 1. Ratio ou consommation | D13: 10 | E13: % | F13: 0 à 30 | G13: Les supports ne sont jamais parfaitement plans.
A14: chape et de ragréage | B14: Rendement du primaire (rendementPrimaire) | C14: 1. Ratio ou consommation | D14: 6 | E14: m² par litre | F14: 1 à —
A15: lino et de sol vinyle en rouleau | B15: Hauteur du raccord (raccord) | C15: 1. Ratio ou consommation | D15: 0 | E15: cm | F15: 0 à 200 | G15: Hauteur de répétition du motif, indiquée par le fabricant.
A16: lino et de sol vinyle en rouleau | B16: Colle par m² (colleM2) | C16: 1. Ratio ou consommation | D16: 0.35 | E16: kg | F16: 0 à — | G16: Indiquée sur le seau selon le revêtement et la spatule.
A17: l’isolation d’un sol | B17: Résistance thermique visée (R) (resistance) | C17: 1. Ratio ou consommation | D17: 3 | E17: m².K/W | F17: 0.5 à 10
A18: l’isolation d’un sol | B18: Conductivité thermique de l’isolant (λ) (lambda) | C18: 1. Ratio ou consommation | D18: 0.03 | E18: W/m.K | F18: 0.015 à 0.1 | G18: Inscrite sur l’emballage des panneaux.
A19: l’isolation d’un sol | B19: Marge pour les découpes (marge) | C19: 1. Ratio ou consommation | D19: 5 | E19: % | F19: 0 à 50
A20: moquette en rouleau | B20: Hauteur du raccord (raccord) | C20: 1. Ratio ou consommation | D20: 0 | E20: cm | F20: 0 à 200 | G20: Hauteur de répétition du motif, indiquée par le fabricant.
A21: moquette en rouleau | B21: Colle par m² (colleM2) | C21: 1. Ratio ou consommation | D21: 0.35 | E21: kg | F21: 0 à — | G21: Indiquée sur le seau selon le revêtement et la spatule.
A22: parquet et de plinthes | B22: Taux de chute personnalisé (tauxChute) | C22: 1. Ratio ou consommation | E22: % | F22: 0 à 50 | G22: Laissez vide pour le taux calculé ou le forfait de la pose.
A23: parquet et de plinthes | B23: Réserve pour la casse et les réparations (reserve) | C23: 1. Ratio ou consommation | D23: 0 | E23: % | F23: 0 à 20
A24: nombre de plinthes | B24: Marge pour les coupes (marge) | C24: 1. Ratio ou consommation | D24: 10 | E24: % | F24: 0 à 30
A25: nombre de plinthes | B25: Mètres collés par cartouche de colle (metresParCartouche) | C25: 1. Ratio ou consommation | D25: 8 | E25: m | F25: 0 à — | G25: Indiqué sur la cartouche ; 0 si les plinthes sont clouées ou vissées.
A26: un plancher chauffant | B26: Longueur maximale d’une boucle (longueurMaxBoucle) | C26: 1. Ratio ou consommation | D26: 100 | E26: m | F26: 20 à — | G26: Selon le diamètre du tube et le fabricant, souvent entre 80 et 120 m.
A27: un plancher chauffant | B27: Marge (marge) | C27: 1. Ratio ou consommation | D27: 5 | E27: % | F27: 0 à 30
A28: carrelage avec découpes | B28: Largeur d’un carreau (largeurCarreau) | C28: 2. Format de produit | D28: 30 | E28: cm | F28: 1 à —
A29: carrelage avec découpes | B29: Longueur d’un carreau (longueurCarreau) | C29: 2. Format de produit | D29: 60 | E29: cm | F29: 1 à —
A30: carrelage avec découpes | B30: Poids d’un sac de colle (poidsSac) | C30: 2. Format de produit | D30: 25 | E30: kg | F30: 1 à —
A31: carrelage avec découpes | B31: Épaisseur des carreaux (epaisseurCarreau) | C31: 2. Format de produit | D31: 9 | E31: mm | F31: 3 à 30 | G31: Sert au calcul du joint.
A32: carrelage avec découpes | B32: Poids d’un sac de joint (poidsSacJoint) | C32: 2. Format de produit | D32: 5 | E32: kg | F32: 1 à —
A33: carrelage avec découpes | B33: Surface d’un rouleau de natte (surfaceNatte) | C33: 2. Format de produit | D33: 5 | E33: m² | F33: 1 à —
A34: chape et de ragréage | B34: Poids d’un sac (poidsSac) | C34: 2. Format de produit | D34: 25 | E34: kg | F34: 1 à —
A35: chape et de ragréage | B35: Contenance d’un bidon de primaire (contenancePrimaire) | C35: 2. Format de produit | D35: 5 | E35: L | F35: 0.5 à —
A36: chape et de ragréage | B36: Longueur d’un rouleau de bande (longueurBande) | C36: 2. Format de produit | D36: 25 | E36: m | F36: 1 à —
A37: lino et de sol vinyle en rouleau | B37: Poids d’un seau de colle (poidsSeau) | C37: 2. Format de produit | D37: 15 | E37: kg | F37: 1 à —
A38: lino et de sol vinyle en rouleau | B38: Longueur d’un rouleau d’adhésif double face (longueurAdhesif) | C38: 2. Format de produit | D38: 25 | E38: m | F38: 1 à —
A39: l’isolation d’un sol | B39: Épaisseur d’un panneau (epaisseurPanneau) | C39: 2. Format de produit | D39: 6 | E39: cm | F39: 1 à —
A40: l’isolation d’un sol | B40: Surface couverte par un colis (surfaceColis) | C40: 2. Format de produit | D40: 4 | E40: m² | F40: 0.1 à —
A41: l’isolation d’un sol | B41: Surface d’un rouleau de film (surfaceFilm) | C41: 2. Format de produit | D41: 50 | E41: m² | F41: 1 à —
...

Sheet Murs intérieurs
A1: Murs intérieurs
A2: Relu par : | C2: Date :
A4: Calculateur | B4: Champ | C4: Catégorie | D4: Valeur par défaut | E4: Unité | F4: Bornes | G4: Aide affichée ou options | H4: Avis | I4: Valeur proposée | J4: Commentaire ou source
A5: carrelage mural et de faïence | B5: Largeur des joints (joint) | C5: 1. Ratio ou consommation | D5: 2 | E5: mm | F5: 0 à 10
A6: carrelage mural et de faïence | B6: Carreaux par carton (carreauxParCarton) | C6: 1. Ratio ou consommation | D6: 8 | F6: 1 à —
A7: carrelage mural et de faïence | B7: Marge pour la casse (marge) | C7: 1. Ratio ou consommation | D7: 10 | E7: % | F7: 0 à 30
A8: carrelage mural et de faïence | B8: Consommation de colle (consommationColle) | C8: 1. Ratio ou consommation | D8: 4 | E8: kg par m² | F8: 0 à —
A9: la quantité de peinture | B9: Nombre de couches (couches) | C9: 1. Ratio ou consommation | D9: 2 | F9: 1 à 5
A10: la quantité de peinture | B10: Rendement de la peinture (rendement) | C10: 1. Ratio ou consommation | D10: 10 | E10: m² par litre | F10: 1 à — | G10: Indiqué sur le pot, pour une couche.
A11: la quantité de peinture | B11: Rendement de la sous-couche (rendementSousCouche) | C11: 1. Ratio ou consommation | D11: 10 | E11: m² par litre | F11: 1 à —
A12: parement mural | B12: Chute de coupe (marge) | C12: 1. Ratio ou consommation | D12: 10 | E12: % | F12: 0 à 30
A13: parement mural | B13: Consommation de mortier-colle (consommationColle) | C13: 1. Ratio ou consommation | D13: 5 | E13: kg par m² | F13: 0 à — | G13: Indiquée sur le sac ; elle dépend du poids des plaquettes.
A14: tenture murale au mètre | B14: Hauteur du raccord (raccord) | C14: 1. Ratio ou consommation | D14: 0 | E14: cm | F14: 0 à 200 | G14: Utile en pose verticale ; en pose horizontale, la marge couvre les raccords aux angles.
A15: tenture murale au mètre | B15: Marge (marge) | C15: 1. Ratio ou consommation | D15: 5 | E15: % | F15: 0 à 30 | G15: Pour les retours d’angle et l’ajustement.
A16: nombre de rouleaux de papier peint | B16: Hauteur du raccord (raccord) | C16: 1. Ratio ou consommation | D16: 0 | E16: cm | F16: 0 à 120 | G16: Hauteur de répétition du motif, inscrite sur l’étiquette à côté du pictogramme (par exemple 53 ou 64 cm).
A17: nombre de rouleaux de papier peint | B17: Rouleaux posés avec un paquet de colle (rouleauxParColle) | C17: 1. Ratio ou consommation | D17: 6 | F17: 1 à — | G17: Indiqué sur le paquet de colle.
A18: carrelage mural et de faïence | B18: Largeur d’un carreau (largeurCarreau) | C18: 2. Format de produit | D18: 30 | E18: cm | F18: 1 à —
A19: carrelage mural et de faïence | B19: Hauteur d’un carreau (hauteurCarreau) | C19: 2. Format de produit | D19: 60 | E19: cm | F19: 1 à —
A20: carrelage mural et de faïence | B20: Surface couverte par un kit de protection (surfaceKitSpec) | C20: 2. Format de produit | D20: 5 | E20: m² | F20: 0.5 à — | G20: Indiquée sur le kit.
A21: carrelage mural et de faïence | B21: Poids d’un sac de colle (poidsSac) | C21: 2. Format de produit | D21: 25 | E21: kg | F21: 1 à —
A22: carrelage mural et de faïence | B22: Épaisseur des carreaux (epaisseurCarreau) | C22: 2. Format de produit | D22: 8 | E22: mm | F22: 3 à 30
A23: carrelage mural et de faïence | B23: Poids d’un sac de joint (poidsSacJoint) | C23: 2. Format de produit | D23: 5 | E23: kg | F23: 1 à —
A24: carrelage mural et de faïence | B24: Longueur d’un profilé (longueurProfile) | C24: 2. Format de produit | D24: 2.5 | E24: m | F24: 1 à —
A25: la quantité de peinture | B25: Contenance d’un pot (contenance) | C25: 2. Format de produit | D25: 2.5 | E25: litres | F25: 0.1 à —
A26: parement mural | B26: Surface couverte par un carton de plaquettes (surfaceCarton) | C26: 2. Format de produit | D26: 0.5 | E26: m² | F26: 0.05 à —
A27: parement mural | B27: Longueur couverte par un carton d’angles (longueurCartonAngles) | C27: 2. Format de produit | D27: 1 | E27: m | F27: 0.1 à —
A28: parement mural | B28: Poids d’un sac de mortier-colle (poidsSac) | C28: 2. Format de produit | D28: 25 | E28: kg | F28: 1 à —
A29: nombre de rouleaux de papier peint | B29: Longueur du rouleau (longueurRouleau) | C29: 2. Format de produit | D29: 10.05 | E29: m | F29: 1 à —
A30: carrelage mural et de faïence | B30: Classe de colle (colle) | C30: 3. Choix proposé | D30: 1 | G30: Options : C1 : colle ordinaire | C2 : colle améliorée | C2 S1 : colle améliorée et déformable Classes de la norme NF EN 12004 ; suivez la fiche de la colle pour le support et le format.
A31: la quantité de peinture | B31: Finition de la peinture des murs (finition) | C31: 3. Choix proposé | D31: 1 | G31: Options : Mate : masque les défauts du mur | Velours : pièces de vie, se nettoie mieux | Satinée : pièces humides, cuisine, boiseries | Brillante : boiseries, effet décoratif Même calcul pour toutes les finitions ; la finition est reprise dans le récapitulatif.
A32: la quantité de peinture | B32: Prévoir une sous-couche d’impression (sousCouche) | C32: 3. Choix proposé | D32: Non cochée | G32: Sur plâtre neuf, support poreux, taché ou changement de couleur marqué.
A33: tenture murale au mètre | B33: Largeur du tissu (laize) (laize) | C33: 3. Choix proposé | D33: 2.8 | G33: Options : 2,80 m, grande largeur posée à l’horizontale | 1,40 m, posée en lés verticaux | 1,30 m, posée en lés verticaux
A34: tenture murale au mètre | B34: Type de raccord (typeRaccord) | C34: 3. Choix proposé | D34: 0 | G34: Options : Libre (uni, sans motif) | Droit | Sauté (décalé) Indiqué sur l’étiquette. Droit : le motif se prolonge à la même hauteur. Sauté : il est décalé d’un lé à l’autre.
A35: nombre de rouleaux de papier peint | B35: Largeur du rouleau (largeurRouleau) | C35: 3. Choix proposé | D35: 0.53 | G35: Options : 0,53 m, format standard | 0,70 m | 1,06 m, grand format intissé
A36: nombre de rouleaux de papier peint | B36: Type de raccord (typeRaccord) | C36: 3. Choix proposé | D36: 0 | G36: Options : Libre (uni, sans motif) | Droit | Sauté (décalé) Indiqué par un pictogramme sur l’étiquette. Droit : le motif se prolonge à la même hauteur. Sauté : il est décalé d’un lé à l’autre.

Sheet Façades
A1: Façades
A2: Relu par : | C2: Date :
A4: Calculateur | B4: Champ | C4: Catégorie | D4: Valeur par défaut | E4: Unité | F4: Bornes | G4: Aide affichée ou options | H4: Avis | I4: Valeur proposée | J4: Commentaire ou source
A5: peinture de façade | B5: Nombre de couches (couches) | C5: 1. Ratio ou consommation | D5: 2 | F5: 1 à 4
A6: peinture de façade | B6: Rendement de la peinture (rendement) | C6: 1. Ratio ou consommation | D6: 6 | E6: m² par litre | F6: 1 à — | G6: Indiqué sur le pot pour une couche ; plus faible sur un crépi ou un enduit rugueux (souvent 4 à 8).
A7: peinture de façade | B7: Rendement du fixateur (rendementFixateur) | C7: 1. Ratio ou consommation | D7: 8 | E7: m² par litre | F7: 1 à —
A8: enduit de façade et de crépi | B8: Consommation par millimètre (consommation) | C8: 1. Ratio ou consommation | D8: 1.4 | E8: kg par m² et par mm | F8: 0.5 à 3 | G8: Indiquée sur la fiche technique du produit.
A9: enduit de façade et de crépi | B9: Marge pour les pertes (marge) | C9: 1. Ratio ou consommation | D9: 10 | E9: % | F9: 0 à 30
A10: une isolation thermique par l’extérieur (ITE) | B10: Résistance thermique visée (R) (resistance) | C10: 1. Ratio ou consommation | D10: 3.7 | E10: m².K/W | F10: 0.5 à 10
A11: une isolation thermique par l’extérieur (ITE) | B11: Conductivité de l’isolant (λ) (lambda) | C11: 1. Ratio ou consommation | D11: 0.032 | E11: W/m.K | F11: 0.015 à 0.06 | G11: Polystyrène graphité : environ 0,031. Polystyrène blanc : environ 0,038. Laine de roche : environ 0,036.
A12: une isolation thermique par l’extérieur (ITE) | B12: Colle (colleM2) | C12: 1. Ratio ou consommation | D12: 5 | E12: kg par m² | F12: 0 à —
A13: une isolation thermique par l’extérieur (ITE) | B13: Chevilles par m² (chevillesM2) | C13: 1. Ratio ou consommation | D13: 6 | F13: 0 à — | G13: Selon le support, la hauteur et l’exposition au vent : voir le cahier technique du système.
A14: une isolation thermique par l’extérieur (ITE) | B14: Enduit de base armé (enduitBaseM2) | C14: 1. Ratio ou consommation | D14: 5 | E14: kg par m² | F14: 0 à —
A15: une isolation thermique par l’extérieur (ITE) | B15: Enduit de finition (finitionM2) | C15: 1. Ratio ou consommation | D15: 2.5 | E15: kg par m² | F15: 0 à —
A16: une isolation thermique par l’extérieur (ITE) | B16: Marge pour les coupes (marge) | C16: 1. Ratio ou consommation | D16: 5 | E16: % | F16: 0 à 30
A17: peinture de façade | B17: Contenance d’un pot (contenance) | C17: 2. Format de produit | D17: 10 | E17: litres | F17: 0.5 à —
A18: enduit de façade et de crépi | B18: Poids d’un sac (poidsSac) | C18: 2. Format de produit | D18: 25 | E18: kg | F18: 1 à —
A19: enduit de façade et de crépi | B19: Surface d’un rouleau de treillis (surfaceTreillis) | C19: 2. Format de produit | D19: 50 | E19: m² | F19: 1 à —
A20: une isolation thermique par l’extérieur (ITE) | B20: Surface d’un panneau (surfacePanneau) | C20: 2. Format de produit | D20: 0.5 | E20: m² | F20: 0.1 à —
A21: une isolation thermique par l’extérieur (ITE) | B21: Poids d’un sac ou d’un seau (poidsSac) | C21: 2. Format de produit | D21: 25 | E21: kg | F21: 1 à —
A22: une isolation thermique par l’extérieur (ITE) | B22: Surface d’un rouleau de treillis (surfaceTreillis) | C22: 2. Format de produit | D22: 50 | E22: m² | F22: 1 à —
A23: peinture de façade | B23: Type de peinture (typePeinture) | C23: 3. Choix proposé | D23: 0 | G23: Options : Acrylique, en phase aqueuse | Pliolite, en phase solvant | Siloxane | Minérale : silicate ou chaux Même calcul pour tous les types ; le rendement dépend du produit, voyez le pot.
A24: peinture de façade | B24: Prévoir un fixateur ou une impression (fixateur) | C24: 3. Choix proposé | D24: Cochée | G24: Sur un support farineux, poreux ou neuf.
A25: enduit de façade et de crépi | B25: Type d’enduit (typeEnduit) | C25: 3. Choix proposé | D25: 0 | G25: Options : Monocouche, à base de ciment | Enduit à la chaux, en plusieurs couches | Crépi ou enduit de finition Adaptez ensuite l’épaisseur et la consommation à la fiche du produit choisi.
A26: enduit de façade et de crépi | B26: Prévoir un treillis d’armature (treillis) | C26: 3. Choix proposé | D26: Non cochée | G26: Renforce l’enduit sur un support hétérogène ou fissuré et aux angles des ouvertures.
A27: une isolation thermique par l’extérieur (ITE) | B27: Isolant (isolant) | C27: 3. Choix proposé | D27: 0 | G27: Options : Autre : λ saisi ci-dessous | Polystyrène graphité (λ ≈ 0,031) | Polystyrène blanc (λ ≈ 0,038) | Laine de roche (λ ≈ 0,036) Valeurs de λ indicatives ; celle du produit choisi figure sur sa fiche technique.

Sheet Charpente
A1: Charpente
A2: Relu par : | C2: Date :
A4: Calculateur | B4: Champ | C4: Catégorie | D4: Valeur par défaut | E4: Unité | F4: Bornes | G4: Aide affichée ou options | H4: Avis | I4: Valeur proposée | J4: Commentaire ou source
A5: nombre de chevrons | B5: Longueur maximale des chevrons vendus (longueurVendue) | C5: 2. Format de produit | D5: 6 | E5: m | F5: 1 à — | G5: Au-delà, un chevron est fait de deux pièces raboutées sur une panne.
A6: nombre de chevrons | B6: Entraxe des chevrons (entraxe) | C6: 3. Choix proposé | D6: 60 | G6: Options : 60 cm | 50 cm | 40 cm
A7: nombre de chevrons | B7: Prévoir des contre-liteaux (écran de sous-toiture) (contreLiteaux) | C7: 3. Choix proposé | D7: Cochée

Sheet Couverture
A1: Couverture
A2: Relu par : | C2: Date :
A4: Calculateur | B4: Champ | C4: Catégorie | D4: Valeur par défaut | E4: Unité | F4: Bornes | G4: Aide affichée ou options | H4: Avis | I4: Valeur proposée | J4: Commentaire ou source
A5: membrane EPDM pour un toit plat | B5: Colle (colleM2) | C5: 1. Ratio ou consommation | D5: 0.3 | E5: litres par m² | F5: 0 à — | G5: Indiquée sur le pot, selon le support.
A6: plaques de couverture et de shingle | B6: Recouvrement entre rangées (recouvrement) | C6: 1. Ratio ou consommation | D6: 20 | E6: cm | F6: 5 à —
A7: plaques de couverture et de shingle | B7: Fixations par plaque (fixationsParPlaque) | C7: 1. Ratio ou consommation | D7: 6 | F7: 1 à —
A8: gouttières et des descentes | B8: Longueur de gouttière par descente (longueurMaxDescente) | C8: 1. Ratio ou consommation | D8: 12 | E8: m | F8: 2 à — | G8: Au-delà, une descente supplémentaire ; à adapter selon le DTU et le fabricant.
A9: nombre de tuiles | B9: Tuiles au m² (tuilesM2) | C9: 1. Ratio ou consommation | D9: 13 | F9: 1 à — | G9: Indiqué par le fabricant : environ 10 à 15 pour une tuile mécanique, bien plus pour une petite tuile plate.
A10: nombre de tuiles | B10: Faîtières par mètre (faitieresParMetre) | C10: 1. Ratio ou consommation | D10: 2.5 | F10: 0.5 à —
A11: nombre de tuiles | B11: Tuiles de rive par mètre (rivesParMetre) | C11: 1. Ratio ou consommation | D11: 3 | F11: 0 à —
A12: nombre de tuiles | B12: Chatières de ventilation pour 10 m² (chatieresPour10m2) | C12: 1. Ratio ou consommation | D12: 1 | F12: 0 à — | G12: La ventilation à prévoir dépend de la toiture et de l’écran : suivez la notice du fabricant ; 0 si aucune.
A13: nombre de tuiles | B13: Marge pour la casse et les coupes (marge) | C13: 1. Ratio ou consommation | D13: 5 | E13: % | F13: 0 à 30
A14: nombre d’ardoises | B14: Recouvrement (recouvrement) | C14: 1. Ratio ou consommation | D14: 10 | E14: cm | F14: 5 à 20 | G14: Selon la pente et la zone : voir le DTU 40.11 ou le fabricant.
A15: nombre d’ardoises | B15: Chatières de ventilation pour 10 m² (chatieresPour10m2) | C15: 1. Ratio ou consommation | D15: 1 | F15: 0 à — | G15: La ventilation à prévoir dépend de la toiture et de l’écran : suivez la notice du fabricant ; 0 si aucune.
A16: nombre d’ardoises | B16: Marge pour la casse et les coupes (marge) | C16: 1. Ratio ou consommation | D16: 7 | E16: % | F16: 0 à 30
A17: membrane EPDM pour un toit plat | B17: Hauteur des relevés (releve) | C17: 2. Format de produit | D17: 15 | E17: cm | F17: 0 à 60 | G17: Hauteur dont la membrane remonte sur les rives ou les acrotères.
A18: membrane EPDM pour un toit plat | B18: Contenance d’un pot de colle (contenancePot) | C18: 2. Format de produit | D18: 5 | E18: L | F18: 0.5 à —
A19: membrane EPDM pour un toit plat | B19: Longueur d’un profilé de rive (longueurProfile) | C19: 2. Format de produit | D19: 2.5 | E19: m | F19: 0.5 à —
A20: plaques de couverture et de shingle | B20: Largeur utile d’une plaque (largeurUtile) | C20: 2. Format de produit | D20: 1 | E20: m | F20: 0.3 à — | G20: Largeur couverte une fois les plaques recouvertes sur le côté.
A21: plaques de couverture et de shingle | B21: Longueur d’une plaque (longueurPlaque) | C21: 2. Format de produit | D21: 2.5 | E21: m | F21: 0.5 à —
A22: plaques de couverture et de shingle | B22: Longueur utile d’une faîtière (longueurFaitiere) | C22: 2. Format de produit | D22: 1 | E22: m | F22: 0.3 à —
A23: plaques de couverture et de shingle | B23: Surface couverte par un paquet de shingle (surfacePaquet) | C23: 2. Format de produit | D23: 3 | E23: m² | F23: 0.5 à —
A24: plaques de couverture et de shingle | B24: Surface d’un rouleau de sous-couche (shingle) (surfaceSousCouche) | C24: 2. Format de produit | D24: 20 | E24: m² | F24: 1 à —
A25: gouttières et des descentes | B25: Longueur d’une gouttière (longueurElement) | C25: 2. Format de produit | D25: 4 | E25: m | F25: 1 à —
A26: gouttières et des descentes | B26: Longueur d’un tuyau de descente (longueurTuyau) | C26: 2. Format de produit | D26: 2 | E26: m | F26: 0.5 à —
A27: nombre de tuiles | B27: Pureau, soit l’écartement des liteaux (pureau) | C27: 2. Format de produit | D27: 34 | E27: cm | F27: 5 à — | G27: Indiqué par le fabricant pour le modèle de tuile et la pente.
A28: nombre de tuiles | B28: Longueur d’un liteau (longueurLiteau) | C28: 2. Format de produit | D28: 4 | E28: m | F28: 1 à —
A29: nombre de tuiles | B29: Surface d’un rouleau d’écran de sous-toiture (surfaceEcran) | C29: 2. Format de produit | D29: 75 | E29: m² | F29: 1 à —
A30: nombre de tuiles | B30: Longueur d’un élément de noue ou de solin (longueurElementZinc) | C30: 2. Format de produit | D30: 2 | E30: m | F30: 0.5 à —
A31: nombre d’ardoises | B31: Longueur d’un liteau (longueurLiteau) | C31: 2. Format de produit | D31: 4 | E31: m | F31: 1 à —
A32: nombre d’ardoises | B32: Surface d’un rouleau d’écran de sous-toiture (surfaceEcran) | C32: 2. Format de produit | D32: 75 | E32: m² | F32: 1 à —
A33: nombre d’ardoises | B33: Surface couverte par une botte de voliges (surfaceBotteVoliges) | C33: 2. Format de produit | D33: 2.5 | E33: m² | F33: 0.5 à —
A34: nombre d’ardoises | B34: Longueur d’un élément de noue ou de solin (longueurElementZinc) | C34: 2. Format de produit | D34: 2 | E34: m | F34: 0.5 à —
A35: plaques de couverture et de shingle | B35: Couverture (type) | C35: 3. Choix proposé | D35: 0 | G35: Options : Plaques ondulées ou bac acier | Bardeaux bitumés (shingle)
A36: nombre d’ardoises | B36: Format des ardoises (format) | C36: 3. Choix proposé | D36: 1 | G36: Options : 32 × 22 cm | 40 × 24 cm | 50 × 25 cm | 60 × 30 cm
